Workbook

Sheet concepts_oct152021
A1: id | B1: name | C1: concept type | D1: medical system | E1: is draft | F1: is epi concept | G1: base kb iri | H1: layman name | I1: is disease-as-risk-factor | J1: original_node_id | K1: layman_question | L1: red_flag | M1: searchable | N1: Triage | O1: Acute/Chronic | P1: last updated Oct 15 2021
A2: 001fa650-28b0-49a1-b36d-76503257d798 | B2: Pain in penis | C2: SYMPTOM | D2: None | E2: False | F2: True | G2: https://bbl.health/87aa1GcS2z | H2: Pain in penis | I2: False | J2: 001fa650-28b0-49a1-b36d-76503257d798 | K2: Do you have pain in your penis? | L2: False | M2: True | N2: None | O2: None
A3: 003eb640-3e58-43c9-9a15-47d92c98120f | B3: Peri-orbital cellulitis | C3: DISEASE | D3: OPHTHALMOLOGY | E3: False | F3: True | G3: https://bbl.health/qjOMB7JE5q | H3: Peri-orbital cellulitis | I3: False | J3: 003eb640-3e58-43c9-9a15-47d92c98120f | L3: False | M3: False | N3: A_E_SELF | O3: NEITHER
A4: 004669a5-428b-4dd6-867c-8421bbb0ba05 | B4: Panic attack | C4: DISEASE | D4: MENTAL_HEALTH | E4: False | F4: True | G4: https://bbl.health/QgkUW3D8Ar | H4: Panic attack | I4: False | J4: 004669a5-428b-4dd6-867c-8421bbb0ba05 | L4: False | M4: False | N4: SELF_CARE | O4: NEITHER
A5: c479ac19-f5b6-5c5d-a1f3-212137e53a8a | B5: Achalasia of oesophagus | C5: DISEASE | D5: GASTROENTEROLOGY_HEPATOLOGY | E5: False | F5: True | G5: https://bbl.health/XcgiRzEcZq | H5: Achalasia of oesophagus | I5: True | J5: e0ef3c11-2964-433c-bb64-b8b4ec15a8b6 | K5: Have you been diagnosed with achalasia of the oesophagus? | L5: False | M5: False | N5: GP | O5: NEITHER
A6: 00aace0c-fb7a-466d-9371-d36cd1cd2aa3 | B6: Exposure to lice or mites | C6: RISK_FACTOR | D6: None | E6: False | F6: True | G6: https://bbl.health/jiXNo61uke | H6: Exposure to lice or mites | I6: False | J6: 00aace0c-fb7a-466d-9371-d36cd1cd2aa3 | K6: Have you recently come into contact with lice or mites? For example from living in close quarters, or sharing clothing or towels with other people. | L6: False | M6: False | N6: None | O6: None
A7: 00be17ce-bd15-48f0-9b35-a5679959a152 | B7: Dietary iodine deficiency | C7: RISK_FACTOR | D7: None | E7: False | F7: True | G7: https://bbl.health/JBLsBKYBZw | H7: Dietary iodine deficiency | I7: False | J7: 00be17ce-bd15-48f0-9b35-a5679959a152 | K7: Is your diet lacking in iodine-rich foods, like seaweed or fish? | L7: False | M7: False | N7: None | O7: None
A8: 01029c68-0a2a-4a0c-872d-10311a774b61 | B8: Epigastric Pain Worse Lying Down | C8: SYMPTOM | D8: None | E8: False | F8: True | G8: https://bbl.health/lcbAguJpZA | H8: Central upper abdominal pain, worse when lying down | I8: False | J8: 01029c68-0a2a-4a0c-872d-10311a774b61 | K8: Is you top-mid abdominal pain worse when lying down? | L8: False | M8: False | N8: None | O8: None
A9: 0143922f-d0c9-42fd-9165-5170996300b9 | B9: Temporomandibular joint-pain-dysfunction syndrome | C9: DISEASE | D9: ENT | E9: False | F9: True | G9: https://bbl.health/dD0Yfhd4FU | H9: TMJ dysfunction | I9: False | J9: 0143922f-d0c9-42fd-9165-5170996300b9 | L9: False | M9: False | N9: GP | O9: NEITHER
A10: 019b0e3a-d932-4694-8014-c4c7615d6191 | B10: No contraceptive precautions (female) | C10: RISK_FACTOR | D10: None | E10: False | F10: True | G10: https://bbl.health/ReB9D1HdeE | H10: No contraceptive precautions | I10: False | J10: 019b0e3a-d932-4694-8014-c4c7615d6191 | K10: Have you had sex in the last 6 months without using condoms and without being covered by another form of reliable contraception which you use effectively? | L10: False | M10: True | N10: None | O10: None
A11: 01e7dc30-406d-40de-8f8e-893cb0fbecad | B11: Retinal artery occlusion | C11: DISEASE | D11: OPHTHALMOLOGY | E11: False | F11: True | G11: https://bbl.health/xstI6_bMju | H11: Retinal artery occlusion | I11: False | J11: 01e7dc30-406d-40de-8f8e-893cb0fbecad | L11: False | M11: False | N11: A_E_SELF | O11: NEITHER
A12: 0250a1f9-1039-45f5-8b99-22b61e906d85 | B12: Benign paroxysmal positional vertigo | C12: DISEASE | D12: ENT | E12: False | F12: True | G12: https://bbl.health/5co4agcN_K | H12: Benign Paroxysmal Positional Vertigo | I12: False | J12: 0250a1f9-1039-45f5-8b99-22b61e906d85 | L12: False | M12: False | N12: GP_URGENT | O12: NEITHER
A13: 029177e2-337b-4a7d-a596-cd4779c6471e | B13: History of panic attacks | C13: RISK_FACTOR | D13: None | E13: False | F13: True | G13: https://bbl.health/wFAKjkGQEI | H13: History of panic attacks | I13: False | J13: 029177e2-337b-4a7d-a596-cd4779c6471e | K13: Have you ever had a panic attack? | L13: False | M13: False | N13: None | O13: None
A14: 02c2d502-49ab-4ce9-89a4-a4bcb51732f1 | B14: Irreducible left lower quadrant abdominal mass | C14: SYMPTOM | D14: None | E14: False | F14: True | G14: https://bbl.health/ygGEiv2TDU | H14: Irreducible mass in left lower part of stomach | I14: False | J14: 02c2d502-49ab-4ce9-89a4-a4bcb51732f1 | K14: Have you noticed a lump or swelling in the left lower part of the stomach which used to come and go but is now stuck out? | L14: True | M14: False | N14: None | O14: None
A15: 02dff1f4-d67a-4e43-85a9-d83eb6259c50 | B15: Constant Right Upper Quadrant Pain | C15: SYMPTOM | D15: None | E15: False | F15: True | G15: https://bbl.health/fQGBE4AHrk | H15: Constant pain in right upper area of stomach | I15: False | J15: 02dff1f4-d67a-4e43-85a9-d83eb6259c50 | K15: Is the pain in the top right of your abdomen there constantly? | L15: False | M15: False | N15: None | O15: None
A16: 03064a04-1a64-46ec-8e0c-3c4f0a85edc6 | B16: FH: Atopy | C16: RISK_FACTOR | D16: None | E16: False | F16: True | G16: https://bbl.health/Orx3x3Cr4H | H16: Family history of allergies | I16: False | J16: 03064a04-1a64-46ec-8e0c-3c4f0a85edc6 | K16: Have either of your parents or any siblings been diagnosed with allergies, asthma, eczema or hay fever? | L16: False | M16: False | N16: None | O16: None
A17: 035d24e1-beff-47e8-92fe-0c9621ac7e74 | B17: Sudden transient loss of vision | C17: SUPER_NODE | D17: None | E17: False | F17: True | G17: https://bbl.health/LxhnPZ-0fa | H17: Temporary loss of vision | I17: False | J17: 035d24e1-beff-47e8-92fe-0c9621ac7e74 | K17: Did you lose your vision temporarily in one or both eyes? | L17: False | M17: True | N17: None | O17: None
A18: 03a12644-a017-4eec-ad0e-e30d13a0d6ba | B18: Lateral epicondyle pain due to movement | C18: SYMPTOM | D18: None | E18: False | F18: True | G18: https://bbl.health/nWIPlx4-l9 | H18: Pain on outer part of elbow when moving | I18: False | J18: 03a12644-a017-4eec-ad0e-e30d13a0d6ba | K18: Do you have pain over the outer aspect of your elbow which is worse with movement? | L18: False | M18: False | N18: None | O18: None
A19: 03af599d-10b1-419d-801c-dd67c63e4ce1 | B19: Sudden Onset Left Upper Quadrant Pain | C19: SYMPTOM | D19: None | E19: False | F19: True | G19: https://bbl.health/wi-gVmtCZ5 | H19: Pain in left upper area of stomach that started suddenly | I19: False | J19: 03af599d-10b1-419d-801c-dd67c63e4ce1 | K19: Did your top left abdominal pain come on suddenly? | L19: False | M19: False | N19: None | O19: None
A20: 03b06810-bb35-43da-a91e-d4100d4fb7d3 | B20: Gynecomastia | C20: SYMPTOM | D20: None | E20: False | F20: True | G20: https://bbl.health/pVolbCroiL | H20: Breast tissue growth | I20: False | J20: 03b06810-bb35-43da-a91e-d4100d4fb7d3 | K20: Does it look like you're developing breasts? | L20: False | M20: True | N20: None | O20: None
A21: 03bfea52-6f3c-491f-affa-e4b59f6d41e7 | B21: Dry skin | C21: SYMPTOM | D21: None | E21: False | F21: True | G21: https://bbl.health/4vGGZeKEFL | H21: Dry skin | I21: False | J21: 03bfea52-6f3c-491f-affa-e4b59f6d41e7 | K21: Have you noticed that your skin is drier than usual? | L21: False | M21: True | N21: None | O21: None
A22: 03e92a60-9e4f-48d0-8fdf-c4c8d8dc759c | B22: Shoulder stiffness after a period of shoulder pain | C22: SYMPTOM | D22: None | E22: False | F22: True | G22: https://bbl.health/2CGWY6T1lv | H22: Shoulder pain followed by stiffness | I22: False | J22: 03e92a60-9e4f-48d0-8fdf-c4c8d8dc759c | K22: Was your shoulder initially painful for a period before becoming stiff? | L22: False | M22: False | N22: None | O22: None
A23: 04025113-3087-41f2-9fec-9eba27670758 | B23: Podoconiosis | C23: DISEASE | D23: MISC | E23: False | F23: True | G23: https://bbl.health/vgju1FliB3 | H23: Nonfilarial elephantiasis | I23: False | J23: 04025113-3087-41f2-9fec-9eba27670758 | L23: False | M23: False | N23: GP_URGENT | O23: NEITHER
A24: 0410b7fa-ddd7-4c7b-b544-2ce95bc2f800 | B24: Unintentional weight loss | C24: SYMPTOM | D24: None | E24: False | F24: True | G24: https://bbl.health/X4MNURoDhw | H24: Unintentional weight loss | I24: False | J24: 0410b7fa-ddd7-4c7b-b544-2ce95bc2f800 | K24: Have you recently lost weight without intending to? | L24: True | M24: True | N24: None | O24: None
A25: 04210e65-22f1-4270-9262-629a263b4027 | B25: Urine consistency frothy | C25: SYMPTOM | D25: None | E25: False | F25: True | G25: https://bbl.health/DaH35h6ENq | H25: Frothy urine | I25: False | J25: 04210e65-22f1-4270-9262-629a263b4027 | K25: Is your urine frothy? | L25: False | M25: True | N25: None | O25: None
A26: 0483d18d-f62d-4c73-9265-b2fc325f5fd7 | B26: Leg pain | C26: SUPER_NODE | D26: None | E26: False | F26: True | G26: https://bbl.health/E0y9z5hwqT | H26: Leg pain | I26: False | J26: 0483d18d-f62d-4c73-9265-b2fc325f5fd7 | K26: Do you have any pain in your leg? | L26: False | M26: True | N26: None | O26: None
A27: 0484c900-1faa-4682-a652-e25f3638fe32 | B27: Personal history of major abdominal surgery | C27: RISK_FACTOR | D27: None | E27: False | F27: True | G27: https://bbl.health/mNjb3pt78- | H27: History of past abdominal surgery | I27: False | J27: 0484c900-1faa-4682-a652-e25f3638fe32 | K27: Have you had abdominal surgery in the past (more than 30 days ago)? | L27: False | M27: False | N27: None | O27: None
A28: 04a3d021-65c7-454e-bef4-c9ab3808c77c | B28: Aching Periumbilical Pain | C28: SYMPTOM | D28: None | E28: False | F28: True | G28: https://bbl.health/sVmtWYAwYC | H28: Aching pain around belly button | I28: False | J28: 04a3d021-65c7-454e-bef4-c9ab3808c77c | K28: Is the pain around your belly button aching in nature? | L28: False | M28: False | N28: None | O28: None
A29: 04c65471-3496-497a-a7d2-2c15f8ca0b4c | B29: Persistent sinus bradycardia | C29: DISEASE | D29: CARDIOLOGY | E29: False | F29: True | G29: https://bbl.health/ifX19JpLYF | H29: Persistent sinus bradycardia | I29: False | J29: 04c65471-3496-497a-a7d2-2c15f8ca0b4c | L29: False | M29: False | N29: GP_URGENT | O29: NEITHER
A30: 04cc7c39-3846-41de-bc46-be574cc2128a | B30: Blistering around mouth | C30: SYMPTOM | D30: None | E30: False | F30: True | G30: https://bbl.health/sCfKdmHdbf | H30: Blisters around mouth | I30: False | J30: 04cc7c39-3846-41de-bc46-be574cc2128a | K30: Have you developed blisters around your mouth? | L30: False | M30: True | N30: None | O30: None
A31: 8b3e98c8-009a-550b-a729-ca778f92ca95 | B31: Addison's disease | C31: DISEASE | D31: ENDOCRINE | E31: False | F31: True | G31: https://bbl.health/XZDIJY8CVH | H31: Addison's disease | I31: True | J31: ddefdccd-dffd-4cd9-a94b-38fba480472f | K31: Have you been diagnosed with Addison's disease? | L31: False | M31: False | N31: GP | O31: NEITHER
A32: 6b6e72a3-8db4-5f2d-a123-38b1ab254815 | B32: Age related macular degeneration | C32: DISEASE | D32: OPHTHALMOLOGY | E32: False | F32: True | G32: https://bbl.health/Rl6D5hEaMG | H32: Age-related Macular Degeneration | I32: True | J32: c588eb39-711e-4562-a0c2-5cbfdfb1fdfe | K32: Have you been diagnosed with macular degeneration? | L32: False | M32: False | N32: GP | O32: NEITHER
A33: 057a6d65-b154-447e-a41b-af687f5009c4 | B33: Lymphedema of lower extremity | C33: DISEASE | D33: GENERAL_SURGERY | E33: False | F33: True | G33: https://bbl.health/f0Ip5rjSZw | H33: Lymphoedema of the leg | I33: False | J33: 057a6d65-b154-447e-a41b-af687f5009c4 | L33: False | M33: False | N33: GP | O33: NEITHER
A34: 0580df85-889d-4bfb-b643-cfc1f2b19cde | B34: Grunting respiration | C34: SYMPTOM | D34: None | E34: False | F34: False | G34: https://bbl.health/xcesKtZHCu | H34: Grunting while breathing | I34: False | J34: 0580df85-889d-4bfb-b643-cfc1f2b19cde | K34: Are you finding breathing difficult to the point you are making a grunting noise while breathing? | L34: False | M34: False | N34: None | O34: None
A35: 05a3a0f6-559d-4ccd-aef1-8484ad4bcc87 | B35: Idiopathic Thrombocytopenic Purpura (ITP) | C35: DISEASE | D35: HAEMATOLOGY | E35: False | F35: True | G35: https://bbl.health/2EdiBbhbB- | H35: Idiopathic Thrombocytopenic Purpura (ITP) | I35: False | J35: 05a3a0f6-559d-4ccd-aef1-8484ad4bcc87 | L35: False | M35: False | N35: GP_URGENT | O35: NEITHER
A36: 06079526-849d-430f-b451-926fff042be1 | B36: Symptoms staying the same | C36: SYMPTOM | D36: None | E36: False | F36: False | G36: https://bbl.health/VLp2s_SqG5 | H36: Symptoms staying the same | I36: False | J36: 06079526-849d-430f-b451-926fff042be1 | K36: Are your symptoms staying the same? | L36: False | M36: False | N36: None | O36: None
A37: 06510181-a035-4ad2-9282-b5e3237b7a1b | B37: Osteoarthritis of wrist | C37: DISEASE | D37: MSK | E37: False | F37: True | G37: https://bbl.health/igbWJMXdtz | H37: Osteoarthritis of wrist | I37: False | J37: 06510181-a035-4ad2-9282-b5e3237b7a1b | L37: False | M37: False | N37: GP | O37: NEITHER
A38: 066145a6-4085-4458-ac5c-1b6db1c9b018 | B38: Bacterial tonsillitis | C38: DISEASE | D38: RESPIRATORY | E38: False | F38: True | G38: https://bbl.health/FL4muki4Kg | H38: Bacterial tonsillitis | I38: False | J38: 066145a6-4085-4458-ac5c-1b6db1c9b018 | L38: False | M38: False | N38: GP_URGENT | O38: NEITHER
A39: 068d276c-287b-4940-87ae-8d38d0da7f4e | B39: Warm red skin of nose | C39: SYMPTOM | D39: None | E39: False | F39: False | G39: https://bbl.health/2pBzUzDrBN | H39: Warm red skin of nose | I39: False | J39: 068d276c-287b-4940-87ae-8d38d0da7f4e | K39: Is the skin on your nose red and warm? | L39: False | M39: False | N39: None | O39: None
A40: 06db6a75-23f7-47db-ae52-0f191acc780e | B40: Dry Mouth | C40: SYMPTOM | D40: None | E40: False | F40: True | G40: https://bbl.health/LNbuZOzirF | H40: Dry mouth | I40: False | J40: 06db6a75-23f7-47db-ae52-0f191acc780e | K40: Is your mouth much drier than usual? | L40: False | M40: True | N40: None | O40: None
...

Sheet concept_synonyms_oct152021
A1: node_id | B1: name | C1: synonym
A2: 001fa650-28b0-49a1-b36d-76503257d798 | B2: Pain in penis | C2: Pain in penis
A3: 001fa650-28b0-49a1-b36d-76503257d798 | B3: Pain in penis | C3: penile pain
A4: 001fa650-28b0-49a1-b36d-76503257d798 | B4: Pain in penis | C4: penis hurts
A5: 001fa650-28b0-49a1-b36d-76503257d798 | B5: Pain in penis | C5: sore penis
A6: 001fa650-28b0-49a1-b36d-76503257d798 | B6: Pain in penis | C6: penis pain
A7: 001fa650-28b0-49a1-b36d-76503257d798 | B7: Pain in penis | C7: painful penis
A8: 001fa650-28b0-49a1-b36d-76503257d798 | B8: Pain in penis | C8: pain in urethra
A9: 019b0e3a-d932-4694-8014-c4c7615d6191 | B9: No contraceptive precautions (female) | C9: Unprotected sex
A10: 019b0e3a-d932-4694-8014-c4c7615d6191 | B10: No contraceptive precautions (female) | C10: Sex without contraception
A11: 019b0e3a-d932-4694-8014-c4c7615d6191 | B11: No contraceptive precautions (female) | C11: Sex without condom
A12: 035d24e1-beff-47e8-92fe-0c9621ac7e74 | B12: Sudden transient loss of vision | C12: Temporary blindness
... A1782: ff3d434f-7ae5-41f4-a974-5ad2c53b16b8 | B1782: Cannot get an erection | C1782: can not get an erection

Sheet flows_oct152021
A1: flow_route_id | B1: concept_id | C1: concept name | D1: flow_intention | E1: apply_to_sex | F1: flow_purpose | G1: flow_id | H1: flow_type | I1: flow_name | J1: apply_to_ages | K1: region | L1: Adult (18+) | M1: Child (<16)
A2: 003ab230-ec61-4861-8f0f-8863c41cb7fa | B2: 6ad11405-d35a-45a8-add5-5222718a09fd | C2: =if($B2="","",vlookup($B2,concepts_oct152021_old!$A:$B,2,false)) -> #REF! | D2: TRIAGE_AND_POSSIBLE_CONDITIONS | E2: UNISEX | F2: TRIAGE_AND_POSSIBLE_CONDITIONS | G2: cough | H2: FLOWBASE_TRIAGE_AND_POSSIBLE_CONDITIONS | I2: cough | J2: {'lt': 16, 'gte': 15} | K2: all | L2: =iferror(search("'gte': 18",J2)>0,FALSE) -> FALSE | M2: =or(iferror(search("'lt': 5",J2)>0,FALSE),iferror(search("13",J2)>0,FALSE),iferror(search("'gte': 15",J2)>0,FALSE)) -> TRUE
A3: 003ab230-ec61-4861-8f0f-8863c41cb7fa | B3: 6ad11405-d35a-45a8-add5-5222718a09fd | C3: =if($B3="","",vlookup($B3,concepts_oct152021_old!$A:$B,2,false)) -> #REF! | D3: TRIAGE_AND_POSSIBLE_CONDITIONS | E3: UNISEX | F3: TRIAGE_AND_POSSIBLE_CONDITIONS | G3: cough | H3: FLOWBASE_TRIAGE_AND_POSSIBLE_CONDITIONS | I3: cough | J3: {'lt': 18, 'gte': 16} | K3: all | L3: =iferror(search("'gte': 18",J3)>0,FALSE) -> FALSE | M3: =or(iferror(search("'lt': 5",J3)>0,FALSE),iferror(search("13",J3)>0,FALSE),iferror(search("'gte': 15",J3)>0,FALSE)) -> FALSE
A4: 003ab230-ec61-4861-8f0f-8863c41cb7fa | B4: 6ad11405-d35a-45a8-add5-5222718a09fd | C4: =if($B4="","",vlookup($B4,concepts_oct152021_old!$A:$B,2,false)) -> #REF! | D4: TRIAGE_AND_POSSIBLE_CONDITIONS | E4: UNISEX | F4: TRIAGE_AND_POSSIBLE_CONDITIONS | G4: cough | H4: FLOWBASE_TRIAGE_AND_POSSIBLE_CONDITIONS | I4: cough | J4: {'gte': 18} | K4: all | L4: =iferror(search("'gte': 18",J4)>0,FALSE) -> TRUE | M4: =or(iferror(search("'lt': 5",J4)>0,FALSE),iferror(search("13",J4)>0,FALSE),iferror(search("'gte': 15",J4)>0,FALSE)) -> FALSE
A5: 007ce8d6-1f25-42d8-8365-b79850ca71ff | B5: 8ee65c3b-0f21-40a9-a51e-f4637f8b152d | C5: =if($B5="","",vlookup($B5,concepts_oct152021_old!$A:$B,2,false)) -> #REF! | D5: TRIAGE | E5: UNISEX | F5: TRIAGE | G5: Hand | H5: CHECKBASE | I5: Hand | J5: {'lt': 5.0, 'gte': 0.0} | K5: all | L5: =iferror(search("'gte': 18",J5)>0,FALSE) -> FALSE | M5: =or(iferror(search("'lt': 5",J5)>0,FALSE),iferror(search("13",J5)>0,FALSE),iferror(search("'gte': 15",J5)>0,FALSE)) -> TRUE
A6: 007ce8d6-1f25-42d8-8365-b79850ca71ff | B6: 8ee65c3b-0f21-40a9-a51e-f4637f8b152d | C6: =if($B6="","",vlookup($B6,concepts_oct152021_old!$A:$B,2,false)) -> #REF! | D6: TRIAGE | E6: UNISEX | F6: TRIAGE | G6: Hand | H6: CHECKBASE | I6: Hand | J6: {'lt': 13.0, 'gte': 5.0} | K6: all | L6: =iferror(search("'gte': 18",J6)>0,FALSE) -> FALSE | M6: =or(iferror(search("'lt': 5",J6)>0,FALSE),iferror(search("13",J6)>0,FALSE),iferror(search("'gte': 15",J6)>0,FALSE)) -> TRUE
A7: 007ce8d6-1f25-42d8-8365-b79850ca71ff | B7: 8ee65c3b-0f21-40a9-a51e-f4637f8b152d | C7: =if($B7="","",vlookup($B7,concepts_oct152021_old!$A:$B,2,false)) -> #REF! | D7: TRIAGE | E7: UNISEX | F7: TRIAGE | G7: Hand | H7: CHECKBASE | I7: Hand | J7: {'lt': 15.0, 'gte': 13.0} | K7: all | L7: =iferror(search("'gte': 18",J7)>0,FALSE) -> FALSE | M7: =or(iferror(search("'lt': 5",J7)>0,FALSE),iferror(search("13",J7)>0,FALSE),iferror(search("'gte': 15",J7)>0,FALSE)) -> TRUE
A8: 007ce8d6-1f25-42d8-8365-b79850ca71ff | B8: 8ee65c3b-0f21-40a9-a51e-f4637f8b152d | C8: =if($B8="","",vlookup($B8,concepts_oct152021_old!$A:$B,2,false)) -> #REF! | D8: TRIAGE | E8: UNISEX | F8: TRIAGE | G8: Hand | H8: CHECKBASE | I8: Hand | J8: {'lt': 16.0, 'gte': 15.0} | K8: all | L8: =iferror(search("'gte': 18",J8)>0,FALSE) -> FALSE | M8: =or(iferror(search("'lt': 5",J8)>0,FALSE),iferror(search("13",J8)>0,FALSE),iferror(search("'gte': 15",J8)>0,FALSE)) -> TRUE
A9: 007ce8d6-1f25-42d8-8365-b79850ca71ff | B9: 8ee65c3b-0f21-40a9-a51e-f4637f8b152d | C9: =if($B9="","",vlookup($B9,concepts_oct152021_old!$A:$B,2,false)) -> #REF! | D9: TRIAGE | E9: UNISEX | F9: TRIAGE | G9: Hand | H9: CHECKBASE | I9: Hand | J9: {'lt': 18.0, 'gte': 16.0} | K9: all | L9: =iferror(search("'gte': 18",J9)>0,FALSE) -> FALSE | M9: =or(iferror(search("'lt': 5",J9)>0,FALSE),iferror(search("13",J9)>0,FALSE),iferror(search("'gte': 15",J9)>0,FALSE)) -> FALSE
A10: 007ce8d6-1f25-42d8-8365-b79850ca71ff | B10: 8ee65c3b-0f21-40a9-a51e-f4637f8b152d | C10: =if($B10="","",vlookup($B10,concepts_oct152021_old!$A:$B,2,false)) -> #REF! | D10: TRIAGE | E10: UNISEX | F10: TRIAGE | G10: Hand | H10: CHECKBASE | I10: Hand | J10: {'gte': 18.0} | K10: all | L10: =iferror(search("'gte': 18",J10)>0,FALSE) -> TRUE | M10: =or(iferror(search("'lt': 5",J10)>0,FALSE),iferror(search("13",J10)>0,FALSE),iferror(search("'gte': 15",J10)>0,FALSE)) -> FALSE
A11: 007e03e2-e8e4-4db1-90fb-4d4ad2b4c35e | B11: 0483d18d-f62d-4c73-9265-b2fc325f5fd7 | C11: =if($B11="","",vlookup($B11,concepts_oct152021_old!$A:$B,2,false)) -> #REF! | D11: TRIAGE | E11: UNISEX | F11: TRIAGE | G11: Leg | H11: CHECKBASE | I11: Leg | J11: {'lt': 5, 'gte': 0} | K11: all | L11: =iferror(search("'gte': 18",J11)>0,FALSE) -> FALSE | M11: =or(iferror(search("'lt': 5",J11)>0,FALSE),iferror(search("13",J11)>0,FALSE),iferror(search("'gte': 15",J11)>0,FALSE)) -> TRUE
A12: 007e03e2-e8e4-4db1-90fb-4d4ad2b4c35e | B12: 0483d18d-f62d-4c73-9265-b2fc325f5fd7 | C12: =if($B12="","",vlookup($B12,concepts_oct152021_old!$A:$B,2,false)) -> #REF! | D12: TRIAGE | E12: UNISEX | F12: TRIAGE | G12: Leg | H12: CHECKBASE | I12: Leg | J12: {'lt': 13, 'gte': 5} | K12: all | L12: =iferror(search("'gte': 18",J12)>0,FALSE) -> FALSE | M12: =or(iferror(search("'lt': 5",J12)>0,FALSE),iferror(search("13",J12)>0,FALSE),iferror(search("'gte': 15",J12)>0,FALSE)) -> TRUE
A13: 007e03e2-e8e4-4db1-90fb-4d4ad2b4c35e | B13: 0483d18d-f62d-4c73-9265-b2fc325f5fd7 | C13: =if($B13="","",vlookup($B13,concepts_oct152021_old!$A:$B,2,false)) -> #REF! | D13: TRIAGE | E13: UNISEX | F13: TRIAGE | G13: Leg | H13: CHECKBASE | I13: Leg | J13: {'lt': 15, 'gte': 13} | K13: all | L13: =iferror(search("'gte': 18",J13)>0,FALSE) -> FALSE | M13: =or(iferror(search("'lt': 5",J13)>0,FALSE),iferror(search("13",J13)>0,FALSE),iferror(search("'gte': 15",J13)>0,FALSE)) -> TRUE
... A2166: a67b2845-8fef-47e5-a07e-9c4470609253 | B2166: 603a4442-f607-48df-88a8-717d01d92741 | C2166: =if($B2166="","",vlookup($B2166,concepts_oct152021_old!$A:$B,2,false)) -> #REF! | D2166: TRIAGE_AND_POSSIBLE_CONDITIONS | E2166: UNISEX | F2166: TRIAGE | G2166: Coronavirus | H2166: FLOWBASE_TRIAGE | I2166: Coronavirus | J2166: {'gte': 18.0} | K2166: USA | L2166: =iferror(search("'gte': 18",J2166)>0,FALSE) -> TRUE | M2166: =or(iferror(search("'lt': 5",J2166)>0,FALSE),iferror(search("13",J2166)>0,FALSE),iferror(search("'gte': 15",J2166)>0,FALSE)) -> FALSE

Sheet MDR Requirement
A1: Node ID | B1: Symptom Name | C1: Concept Type | D1: Searchable for PGM (TRUE/FALSE) | E1: Searchable for Checkbase Adult (TRUE/FALSE) | F1: Searchable for Checkbase Paediatrics (TRUE/FALSE)
A2: 001fa650-28b0-49a1-b36d-76503257d798 | B2: Pain in penis | C2: SYMPTOM | D2: True | E2: True | F2: True
A3: 003eb640-3e58-43c9-9a15-47d92c98120f | B3: Peri-orbital cellulitis | C3: DISEASE | D3: False | E3: False | F3: False
A4: 004669a5-428b-4dd6-867c-8421bbb0ba05 | B4: Panic attack | C4: DISEASE | D4: False | E4: False | F4: False
A5: 7b3cd23a-c400-5552-900c-87c46cc7d155 | B5: Chronic Pancreatitis | C5: DISEASE | D5: False | E5: False | F5: False
A6: 00aace0c-fb7a-466d-9371-d36cd1cd2aa3 | B6: Exposure to lice or mites | C6: RISK_FACTOR | D6: False | E6: False | F6: False
A7: 00be17ce-bd15-48f0-9b35-a5679959a152 | B7: Dietary iodine deficiency | C7: RISK_FACTOR | D7: False | E7: False | F7: False
A8: 01029c68-0a2a-4a0c-872d-10311a774b61 | B8: Epigastric Pain Worse Lying Down | C8: SYMPTOM | D8: False | E8: False | F8: False
A9: 0143922f-d0c9-42fd-9165-5170996300b9 | B9: Temporomandibular joint-pain-dysfunction syndrome | C9: DISEASE | D9: False | E9: False | F9: False
A10: 019b0e3a-d932-4694-8014-c4c7615d6191 | B10: No contraceptive precautions (female) | C10: RISK_FACTOR | D10: True | E10: False | F10: False
A11: 01e7dc30-406d-40de-8f8e-893cb0fbecad | B11: Retinal artery occlusion | C11: DISEASE | D11: False | E11: False | F11: False
A12: 0250a1f9-1039-45f5-8b99-22b61e906d85 | B12: Benign paroxysmal positional vertigo | C12: DISEASE | D12: False | E12: False | F12: False
... A1590: ffbd5f4e-d64a-49c5-ac12-bc69ed29d5db | B1590: Viral upper respiratory tract infection | C1590: DISEASE | D1590: False | E1590: False | F1590: False

Sheet concept_regionality_oct152021
A1: node_id | B1: region | D1: last updated Oct 15 2021
A2: 001fa650-28b0-49a1-b36d-76503257d798 | B2: all_regions
A3: 003eb640-3e58-43c9-9a15-47d92c98120f | B3: all_regions
A4: 004669a5-428b-4dd6-867c-8421bbb0ba05 | B4: all_regions
A5: 7b3cd23a-c400-5552-900c-87c46cc7d155 | B5: all_regions
A6: 00aace0c-fb7a-466d-9371-d36cd1cd2aa3 | B6: cambodia
A7: 00aace0c-fb7a-466d-9371-d36cd1cd2aa3 | B7: indonesia
A8: 00aace0c-fb7a-466d-9371-d36cd1cd2aa3 | B8: philippines
A9: 00aace0c-fb7a-466d-9371-d36cd1cd2aa3 | B9: rwanda
A10: 00aace0c-fb7a-466d-9371-d36cd1cd2aa3 | B10: vietnam
A11: 00aace0c-fb7a-466d-9371-d36cd1cd2aa3 | B11: myanmar
A12: 00aace0c-fb7a-466d-9371-d36cd1cd2aa3 | B12: laos
A13: 00be17ce-bd15-48f0-9b35-a5679959a152 | B13: all_regions
... A2228: ffbd5f4e-d64a-49c5-ac12-bc69ed29d5db | B2228: all_regions

Sheet concepts_sept282021 
A1: Guv Y=red flag, M=maybe, N=not red flag symptom | B1: Guv shorthand review | C1: id | D1: name | E1: concept type | F1: medical system | G1: is draft | H1: is epi concept | I1: base kb iri | J1: layman name | K1: is disease-as-risk-factor | L1: original_node_id | M1: layman_question | N1: red_flag | O1: last updated Sept 28 2021
A2: M | B2: m | C2: 19336386-41eb-4ced-99ee-aaff396bf720 | D2: Oliguria | E2: SYMPTOM | F2: None | G2: False | H2: True | I2: https://bbl.health/yTLvSRZREp | J2: Little urine passed in 24 hours | K2: False | L2: 19336386-41eb-4ced-99ee-aaff396bf720 | M2: Have you passed very little urine today? | N2: False
A3: M | B3: m | C3: 3948e1d7-a894-4dc9-b293-45be82543289 | D3: Diarrhea | E3: SYMPTOM | F3: None | G3: False | H3: True | I3: https://bbl.health/HN04E_WaPN | J3: Diarrhoea | K3: False | L3: 3948e1d7-a894-4dc9-b293-45be82543289 | M3: Do you have diarrhoea? | N3: True
A4: N | B4: m | C4: 4149234e-72dc-48b5-9bcc-50eb9b6c6e94 | D4: Nocturnal diarrhoea | E4: SYMPTOM | F4: None | G4: False | H4: True | I4: https://bbl.health/v38OE_Qiwf | J4: Diarrhoea at night | K4: False | L4: 4149234e-72dc-48b5-9bcc-50eb9b6c6e94 | M4: Do you regularly have diarrhoea at night? | N4: False
A5: N | B5: m | C5: 5dc744a2-55b8-4bb2-b532-9e7900bf85a4 | D5: Pruritus of skin | E5: SYMPTOM | F5: None | G5: False | H5: True | I5: https://bbl.health/lEiraUaTiX | J5: Itchy skin | K5: False | L5: 5dc744a2-55b8-4bb2-b532-9e7900bf85a4 | M5: Is your skin itchy? | N5: False
A6: N | B6: m | C6: 7bee3797-ebb0-422c-beac-4309e8b43512 | D6: Anxiety | E6: SUPER_NODE | F6: None | G6: False | H6: True | I6: https://bbl.health/nFboaTRruM | J6: Anxiety | K6: False | L6: 7bee3797-ebb0-422c-beac-4309e8b43512 | M6: Are you feeling unusually anxious, to the point where it's affecting your day-to-day life? | N6: False
A7: N | B7: m | C7: 9a19c875-9ae9-4abf-b425-1a62d751b737 | D7: Painful lips | E7: SYMPTOM | F7: None | G7: False | H7: True | I7: https://bbl.health/NmnV8FFS36 | J7: Pain around the mouth | K7: False | L7: 9a19c875-9ae9-4abf-b425-1a62d751b737 | M7: Do you have any pain around your lips? | N7: False
A8: N | B8: m | C8: a23faa73-c2ca-4303-a674-ad94dbcfcd6d | D8: Tenesmus | E8: SYMPTOM | F8: None | G8: False | H8: True | I8: https://bbl.health/QLacLNYtiO | J8: Bowels feel full after passing stool | K8: False | L8: a23faa73-c2ca-4303-a674-ad94dbcfcd6d | M8: Does it feel like you haven't completed passing stool after having used the toilet? | N8: False
A9: M | B9: m | C9: c0ad1d9a-0859-4e51-9a8f-f5809cb55901 | D9: Hoarse | E9: SYMPTOM | F9: None | G9: False | H9: True | I9: https://bbl.health/Pv4PNLrOnr | J9: Hoarse voice | K9: False | L9: c0ad1d9a-0859-4e51-9a8f-f5809cb55901 | M9: Have you noticed any hoarseness in your voice? | N9: True
A10: N | B10: m | C10: f3ad340b-d6ce-4148-b6de-2925be53013e | D10: Dribbling of urine | E10: SYMPTOM | F10: None | G10: False | H10: True | I10: https://bbl.health/6vkekCG6al | J10: Dribbling of urine | K10: False | L10: f3ad340b-d6ce-4148-b6de-2925be53013e | M10: Have you noticed that your urine dribbles at the end of the flow? | N10: False
A11: Y | B11: m | C11: 67bff195-56f5-4926-873d-45cf93d73139 | D11: Non-blanching rash | E11: SYMPTOM | F11: None | G11: False | H11: True | I11: https://bbl.health/WG7xRUgDin | J11: Rash that doesn't go away when pressed | K11: False | L11: 67bff195-56f5-4926-873d-45cf93d73139 | M11: Do you have a rash that doesn't become lighter in colour when you press on it? | N11: True
A12: N | B12: A | C12: 073fe57d-6808-4719-a800-ed973e82e3f5 | D12: Gradual onset eye pain (bilateral) | E12: SYMPTOM | F12: None | G12: False | H12: True | I12: https://bbl.health/F544OP8mc3 | J12: Pain in both eyes that started gradually | K12: False | L12: 073fe57d-6808-4719-a800-ed973e82e3f5 | M12: Do you have pain in both eyes? | N12: False
A13: N | B13: A | C13: b72d03c9-99c6-46f0-aa55-9a69faa52b65 | D13: Burning Loin Pain | E13: SYMPTOM | F13: None | G13: False | H13: True | I13: https://bbl.health/ArLzKj440y | J13: Burning pain in side | K13: False | L13: b72d03c9-99c6-46f0-aa55-9a69faa52b65 | M13: Is the pain in your loins burning in nature? | N13: False
... A663: N | B663: A | C663: ff3d434f-7ae5-41f4-a974-5ad2c53b16b8 | D663: Cannot get an erection | E663: SYMPTOM | F663: None | G663: False | H663: True | I663: https://bbl.health/fGXzq-WZ-x | J663: Cannot achieve erection | K663: False | L663: ff3d434f-7ae5-41f4-a974-5ad2c53b16b8 | M663: Do you experience difficulty in achieving an erection? | N663: False
C664: 003eb640-3e58-43c9-9a15-47d92c98120f | D664: Peri-orbital cellulitis | E664: DISEASE | F664: OPHTHALMOLOGY | G664: False | H664: True | I664: https://bbl.health/qjOMB7JE5q | J664: Peri-orbital cellulitis | K664: False | L664: 003eb640-3e58-43c9-9a15-47d92c98120f | M664: None | N664: False
C665: 004669a5-428b-4dd6-867c-8421bbb0ba05 | D665: Panic attack | E665: DISEASE | F665: MENTAL_HEALTH | G665: False | H665: True | I665: https://bbl.health/QgkUW3D8Ar | J665: Panic attack | K665: False | L665: 004669a5-428b-4dd6-867c-8421bbb0ba05 | M665: None | N665: False
C666: 7b3cd23a-c400-5552-900c-87c46cc7d155 | D666: Chronic Pancreatitis | E666: DISEASE | F666: GASTROENTEROLOGY_HEPATOLOGY | G666: False | H666: True | I666: https://bbl.health/1aQ5drg4Bk | J666: Chronic pancreatitis | K666: True | L666: 008e744b-596c-44f8-9239-dd711f5212fc | M666: Have you been diagnosed with chronic pancreatitis? | N666: False
C667: 00aace0c-fb7a-466d-9371-d36cd1cd2aa3 | D667: Exposure to lice or mites | E667: RISK_FACTOR | F667: None | G667: False | H667: True | I667: https://bbl.health/jiXNo61uke | J667: Exposure to lice or mites | K667: False | L667: 00aace0c-fb7a-466d-9371-d36cd1cd2aa3 | M667: Have you recently come into contact with lice or mites? For example from living in close quarters, or sharing clothing or towels with other people. | N667: False
C668: 00be17ce-bd15-48f0-9b35-a5679959a152 | D668: Dietary iodine deficiency | E668: RISK_FACTOR | F668: None | G668: False | H668: True | I668: https://bbl.health/JBLsBKYBZw | J668: Dietary iodine deficiency | K668: False | L668: 00be17ce-bd15-48f0-9b35-a5679959a152 | M668: Is your diet lacking in iodine-rich foods, like seaweed or fish? | N668: False
C669: 0143922f-d0c9-42fd-9165-5170996300b9 | D669: Temporomandibular joint-pain-dysfunction syndrome | E669: DISEASE | F669: ENT | G669: False | H669: True | I669: https://bbl.health/dD0Yfhd4FU | J669: TMJ dysfunction | K669: False | L669: 0143922f-d0c9-42fd-9165-5170996300b9 | M669: None | N669: False
C670: 019b0e3a-d932-4694-8014-c4c7615d6191 | D670: No contraceptive precautions (female) | E670: RISK_FACTOR | F670: None | G670: False | H670: True | I670: https://bbl.health/ReB9D1HdeE | J670: No contraceptive precautions | K670: False | L670: 019b0e3a-d932-4694-8014-c4c7615d6191 | M670: Have you had sex in the last 6 months without using condoms and without being covered by another form of reliable contraception which you use effectively? | N670: False
C671: 01e7dc30-406d-40de-8f8e-893cb0fbecad | D671: Retinal artery occlusion | E671: DISEASE | F671: OPHTHALMOLOGY | G671: False | H671: True | I671: https://bbl.health/xstI6_bMju | J671: Retinal artery occlusion | K671: False | L671: 01e7dc30-406d-40de-8f8e-893cb0fbecad | M671: None | N671: False
C672: 0250a1f9-1039-45f5-8b99-22b61e906d85 | D672: Benign paroxysmal positional vertigo | E672: DISEASE | F672: ENT | G672: False | H672: True | I672: https://bbl.health/5co4agcN_K | J672: Benign Paroxysmal Positional Vertigo | K672: False | L672: 0250a1f9-1039-45f5-8b99-22b61e906d85 | M672: None | N672: False
C673: 029177e2-337b-4a7d-a596-cd4779c6471e | D673: History of panic attacks | E673: RISK_FACTOR | F673: None | G673: False | H673: True | I673: https://bbl.health/wFAKjkGQEI | J673: History of panic attacks | K673: False | L673: 029177e2-337b-4a7d-a596-cd4779c6471e | M673: Have you ever had a panic attack? | N673: False
C674: 03064a04-1a64-46ec-8e0c-3c4f0a85edc6 | D674: FH: Atopy | E674: RISK_FACTOR | F674: None | G674: False | H674: True | I674: https://bbl.health/Orx3x3Cr4H | J674: Family history of allergies | K674: False | L674: 03064a04-1a64-46ec-8e0c-3c4f0a85edc6 | M674: Have either of your parents or any siblings been diagnosed with allergies, asthma, eczema or hay fever? | N674: False
C675: 04025113-3087-41f2-9fec-9eba27670758 | D675: Podoconiosis | E675: DISEASE | F675: MISC | G675: False | H675: True | I675: https://bbl.health/vgju1FliB3 | J675: Nonfilarial elephantiasis | K675: False | L675: 04025113-3087-41f2-9fec-9eba27670758 | M675: None | N675: False
... C694: c136f130-9947-564c-860a-c0b362373db9 | D694: Malignant neoplasm of nasopharynx | E694: DISEASE | F694: ENT | G694: False | H694: True | I694: https://bbl.health/ONJyFjVdsq | J694: Nasopharyngeal Cancer | K694: True | L694: 08e079d5-76d2-4cb2-8e8a-220376df1151 | M694: Have you been diagnosed with nasopharyngeal cancer? | N694: False
A695: Y | B695: A | C695: 0902d677-d8bf-442d-8b8c-e4e147667777 | D695: Unilateral paresthesia of upper limb | E695: SYMPTOM | F695: None | G695: False | H695: True | I695: https://bbl.health/pUs16y77Hi | J695: Pins and needles in one arm | K695: False | L695: 0902d677-d8bf-442d-8b8c-e4e147667777 | M695: Do you have pins and needles in one of your arms? | N695: False
C696: 0938acb7-01ce-4ffe-81c9-7b25a3962001 | D696: History of cancer | E696: RISK_FACTOR | F696: None | G696: False | H696: False | I696: https://bbl.health/1lN7Xk0HPh | J696: History of cancer | K696: False | L696: 0938acb7-01ce-4ffe-81c9-7b25a3962001 | M696: Have you ever had a diagnosis of cancer? | N696: False
C697: 8038058c-a44b-5c5c-8c83-5147eeaafeb8 | D697: Uncomplicated inguinal hernia | E697: DISEASE | F697: GENERAL_SURGERY | G697: False | H697: True | I697: https://bbl.health/aDtKvdFnlC | J697: Uncomplicated inguinal hernia | K697: True | L697: 09546181-fdb1-41c9-997f-ef372ff3fab5 | M697: Do you currently have a inguinal hernia? | N697: False
C698: 2eeea714-756a-54bc-9f1d-ba579fb7b407 | D698: Type 1 diabetes mellitus | E698: DISEASE | F698: ENDOCRINE | G698: False | H698: True | I698: https://bbl.health/O1B9tzxsCv | J698: Type 1 diabetes | K698: True | L698: 097d08ac-1fda-45d9-9a79-09f439f305de | M698: Have you been diagnosed with type 1 diabetes? | N698: False
C699: 098c10ed-b89c-42e9-a0a0-518217da4b94 | D699: Chikungunya | E699: DISEASE | F699: MISC | G699: False | H699: True | I699: https://bbl.health/doqlKxOm0x | J699: Chikungunya | K699: False | L699: 098c10ed-b89c-42e9-a0a0-518217da4b94 | M699: None | N699: False
C700: 09b87963-4fcf-4015-a059-6bdd87c6c1f0 | D700: Family history of psoriasis with arthropathy | E700: RISK_FACTOR | F700: None | G700: False | H700: True | I700: https://bbl.health/KdhXlldG7l | J700: Family history of psoriatic arthritis | K700: False | L700: 09b87963-4fcf-4015-a059-6bdd87c6c1f0 | M700: Have either of your parents, or any siblings, ever been diagnosed with psoriatic arthritis? | N700: False
C701: 09cf7b8a-8fbf-4088-98a6-1b75d14effad | D701: Serous nipple discharge (unisex) | E701: SYMPTOM | F701: None | G701: False | H701: False | I701: https://bbl.health/hXQPWxkhMT | J701: Watery nipple discharge | K701: False | L701: 09cf7b8a-8fbf-4088-98a6-1b75d14effad | M701: Do you have watery or pale clear discharge from your nipple? | N701: False
C702: 0a11166a-6649-4718-81b4-df4ef69f1168 | D702: Laryngitis | E702: DISEASE | F702: ENT | G702: False | H702: True | I702: https://bbl.health/HzYJz5SJBW | J702: Inflammation of the voice box | K702: False | L702: 0a11166a-6649-4718-81b4-df4ef69f1168 | M702: None | N702: False
C703: da4e3c73-252b-53a3-bc86-8efd0012daf3 | D703: Osteoarthritis of knee | E703: DISEASE | F703: MSK | G703: False | H703: True | I703: https://bbl.health/tsVgyzZr1U | J703: Osteoarthritis of knee | K703: True | L703: 0ae2b137-5df5-4741-8a4d-d3c44abd1008 | M703: Have you been diagnosed with osteoarthritis of the knee? | N703: False
C704: 0af03be8-6be5-4171-bacb-a7d0474a3494 | D704: History of vaginal delivery | E704: RISK_FACTOR | F704: None | G704: False | H704: True | I704: https://bbl.health/ZoTD70WdQV | J704: Previous vaginal delivery | K704: False | L704: 0af03be8-6be5-4171-bacb-a7d0474a3494 | M704: Have you given birth by vaginal delivery? | N704: False
C705: 0b76a8b9-7ecd-4b73-b503-95af0dd20d97 | D705: Bite of insect | E705: SYMPTOM | F705: None | G705: False | H705: False | I705: https://bbl.health/4KTrWFNDHe | J705: Insect bite or sting | K705: False | L705: 0b76a8b9-7ecd-4b73-b503-95af0dd20d97 | M705: Have you been bitten or stung by an insect recently? | N705: False
C706: 0b7a9ed6-feb6-4f2a-9125-404e9333f76f | D706: Globus pharyngeus | E706: DISEASE | F706: ENT | G706: False | H706: True | I706: https://bbl.health/ogF-Cc6Xv6 | J706: Globus pharyngeus | K706: False | L706: 0b7a9ed6-feb6-4f2a-9125-404e9333f76f | M706: None | N706: False
C707: 0c64c498-1da3-48fe-a99e-7a34832b5a24 | D707: Ascending cholangitis | E707: DISEASE | F707: GASTROENTEROLOGY_HEPATOLOGY | G707: False | H707: True | I707: https://bbl.health/uLwdd0-JcW | J707: Ascending cholangitis | K707: False | L707: 0c64c498-1da3-48fe-a99e-7a34832b5a24 | M707: None | N707: False
...

Sheet associations_sept282021
A1: from_node_id | B1: to_node_id | C1: Concept names | D1: **note: node ids are post-drf mapping | E1: last updated sept 28 2021
A2: d56675c1-6ab7-4c64-9f87-beba5f6eeff0 | B2: 26feba86-1824-413f-84a2-1a7370c19590 | C2: Acute exacerbation of chronic obstructive airways disease -> Chest Pain at Rest
A3: 94467aba-a89c-4292-91ea-f523622e62b9 | B3: 3daeffeb-2c76-40b2-8bef-187fa1c899b1 | C3: Benign intracranial space occupying lesion -> Weakness of hand
A4: 2eeea714-756a-54bc-9f1d-ba579fb7b407 | B4: 98b299b5-1b3e-44de-89b5-78c624a9d4a4 | C4: Type 1 diabetes mellitus -> Vulvitis
A5: 7987e079-112d-468f-ab8d-5c9e6378e0a5 | B5: 0410b7fa-ddd7-4c7b-b544-2ce95bc2f800 | C5: AIDS -> Unintentional weight loss
A6: 8b8dd2eb-fba5-4c66-b863-bef4d116d593 | B6: 66792b41-c3b1-477f-9a91-7ee575a01b4b | C6: Duct ectasia -> Intermittent Pain of Breast
A7: e43db90b-f1fc-4b11-833d-7065a6cd95d2 | B7: 7e011c54-ba88-5e7b-b019-8829a48d43d4 | C7: Lifting heavy objects -> Uncomplicated femoral hernia
A8: cebe5a92-ea5e-4927-8ce4-ce0a11ab416b | B8: 5ad37faa-efa1-4a28-bfba-e8dc41283e20 | C8: Balanitis -> Erythema of male genitals
A9: 737ac07f-76e1-4fd6-995a-046e716fa94f | B9: cd4c5fb4-21bc-4e13-ac50-6eee8d24e769 | C9: Amoebiasis -> Duration of symptoms identified
A10: 5bff05cb-e08c-481e-ab65-69d59a57a682 | B10: f1714d47-e776-4788-969f-8adecc6457ba | C10: Obesity -> Ruptured abdominal aortic aneurysm
A11: f11242b8-f9cd-5010-9f2e-54ec798482a2 | B11: ef97a43a-33df-49fb-b552-56b51a7c1985 | C11: Gastritis -> Severe Left Upper Quadrant Pain
A12: 5de132ef-5d20-49b9-8f59-4a87c71f211e | B12: f5aaa5a5-b6b7-430d-b9e5-730794a794f1 | C12: Subarachnoid haemorrhage -> Ataxia
A13: bd9a340a-f40b-55a9-8725-a5b26c0367d3 | B13: cd939b8d-fcc3-599e-a0c6-a6d4a2f19f4d | C13: Hepatitis C -> Malignant neoplasm of liver
... A13438: 1b778514-33a0-4c3d-9208-d2567fee86f6 | B13438: e0ee0c4b-6481-4aa2-9010-244fc1d8a4fe | C13438: Colonic polyp -> Stabbing Right Upper Quadrant Pain

Sheet answers_us_deepsouth_8.9
A1: question_id | B1: question_text_key | C1: question_text | D1: url | E1: is_epi_question | F1: sex | G1: answer_id | H1: node_id | I1: answer_text_key | J1: answer_text | K1: answer_state | L1: can_multiselect | N1: source
A2: 00089354-415a-4651-9e17-370c8227adb7 | B2: question_00089354-415a-4651-9e17-370c8227adb7_text | C2: Is the swelling in your big toe? | D2: https://aim-dashboard.internal.babylontech.co.uk/questions/UXVlc3Rpb246MDAwODkzNTQtNDE1YS00NjUxLTllMTctMzcwYzgyMjdhZGI3 | E2: True | F2: unisex | G2: 8c855e4c-f5ba-4eac-86fe-ea2717c908b1 | H2: 8a5421fd-271d-4a09-84f5-2902540b4a18 | I2: answer_8c855e4c-f5ba-4eac-86fe-ea2717c908b1_text | J2: Yes | K2: present | L2: False | N2: https://github.com/babylonhealth/diagnostic-engine-models/blob/master/components/diagnostic_engine/us-deep-south-to-great-lakes-dolphin-8.9/all_questions.json
A3: 00089354-415a-4651-9e17-370c8227adb7 | B3: question_00089354-415a-4651-9e17-370c8227adb7_text | C3: Is the swelling in your big toe? | D3: https://aim-dashboard.internal.babylontech.co.uk/questions/UXVlc3Rpb246MDAwODkzNTQtNDE1YS00NjUxLTllMTctMzcwYzgyMjdhZGI3 | E3: True | F3: unisex | G3: 00089354-415a-4651-9e17-370c8227adb7_none | I3: question_00089354-415a-4651-9e17-370c8227adb7_none_text | J3: No | K3: absent | L3: False | N3: **US only**
A4: 00089354-415a-4651-9e17-370c8227adb7 | B4: question_00089354-415a-4651-9e17-370c8227adb7_text | C4: Is the swelling in your big toe? | D4: https://aim-dashboard.internal.babylontech.co.uk/questions/UXVlc3Rpb246MDAwODkzNTQtNDE1YS00NjUxLTllMTctMzcwYzgyMjdhZGI3 | E4: True | F4: unisex | G4: 00089354-415a-4651-9e17-370c8227adb7_unknown | I4: dont_know | J4: I don't know | K4: unknown | L4: False
A5: 001fa650-28b0-49a1-b36d-76503257d798 | B5: node_001fa650-28b0-49a1-b36d-76503257d798_layman_question | C5: Do you have pain in your penis? | D5: https://aim-dashboard.internal.babylontech.co.uk/concept/Q29uY2VwdDowMDFmYTY1MC0yOGIwLTQ5YTEtYjM2ZC03NjUwMzI1N2Q3OTg= | E5: True | F5: male_only | G5: 001fa650-28b0-49a1-b36d-76503257d798_present | H5: 001fa650-28b0-49a1-b36d-76503257d798 | I5: node_001fa650-28b0-49a1-b36d-76503257d798_layman_question_yes | J5: Yes | K5: present | L5: False
A6: 001fa650-28b0-49a1-b36d-76503257d798 | B6: node_001fa650-28b0-49a1-b36d-76503257d798_layman_question | C6: Do you have pain in your penis? | D6: https://aim-dashboard.internal.babylontech.co.uk/concept/Q29uY2VwdDowMDFmYTY1MC0yOGIwLTQ5YTEtYjM2ZC03NjUwMzI1N2Q3OTg= | E6: True | F6: male_only | G6: 001fa650-28b0-49a1-b36d-76503257d798_absent | H6: 001fa650-28b0-49a1-b36d-76503257d798 | I6: node_001fa650-28b0-49a1-b36d-76503257d798_layman_question_no | J6: No | K6: absent | L6: False
A7: 001fa650-28b0-49a1-b36d-76503257d798 | B7: node_001fa650-28b0-49a1-b36d-76503257d798_layman_question | C7: Do you have pain in your penis? | D7: https://aim-dashboard.internal.babylontech.co.uk/concept/Q29uY2VwdDowMDFmYTY1MC0yOGIwLTQ5YTEtYjM2ZC03NjUwMzI1N2Q3OTg= | E7: True | F7: male_only | G7: 001fa650-28b0-49a1-b36d-76503257d798_unknown | I7: dont_know | J7: I don't know | K7: unknown | L7: False
A8: 00aace0c-fb7a-466d-9371-d36cd1cd2aa3 | B8: node_00aace0c-fb7a-466d-9371-d36cd1cd2aa3_layman_question | C8: Have you been exposed to lice or mites, for example through living in close quarters or sharing clothing/towels with other people? | D8: https://aim-dashboard.internal.babylontech.co.uk/concept/Q29uY2VwdDowMGFhY2UwYy1mYjdhLTQ2NmQtOTM3MS1kMzZjZDFjZDJhYTM= | E8: True | F8: unisex | G8: 00aace0c-fb7a-466d-9371-d36cd1cd2aa3_present | H8: 00aace0c-fb7a-466d-9371-d36cd1cd2aa3 | I8: node_00aace0c-fb7a-466d-9371-d36cd1cd2aa3_layman_question_yes | J8: Yes | K8: present | L8: False
A9: 00aace0c-fb7a-466d-9371-d36cd1cd2aa3 | B9: node_00aace0c-fb7a-466d-9371-d36cd1cd2aa3_layman_question | C9: Have you been exposed to lice or mites, for example through living in close quarters or sharing clothing/towels with other people? | D9: https://aim-dashboard.internal.babylontech.co.uk/concept/Q29uY2VwdDowMGFhY2UwYy1mYjdhLTQ2NmQtOTM3MS1kMzZjZDFjZDJhYTM= | E9: True | F9: unisex | G9: 00aace0c-fb7a-466d-9371-d36cd1cd2aa3_absent | H9: 00aace0c-fb7a-466d-9371-d36cd1cd2aa3 | I9: node_00aace0c-fb7a-466d-9371-d36cd1cd2aa3_layman_question_no | J9: No | K9: absent | L9: False
A10: 00aace0c-fb7a-466d-9371-d36cd1cd2aa3 | B10: node_00aace0c-fb7a-466d-9371-d36cd1cd2aa3_layman_question | C10: Have you been exposed to lice or mites, for example through living in close quarters or sharing clothing/towels with other people? | D10: https://aim-dashboard.internal.babylontech.co.uk/concept/Q29uY2VwdDowMGFhY2UwYy1mYjdhLTQ2NmQtOTM3MS1kMzZjZDFjZDJhYTM= | E10: True | F10: unisex | G10: 00aace0c-fb7a-466d-9371-d36cd1cd2aa3_unknown | I10: dont_know | J10: I don't know | K10: unknown | L10: False
A11: 00be17ce-bd15-48f0-9b35-a5679959a152 | B11: node_00be17ce-bd15-48f0-9b35-a5679959a152_layman_question | C11: Is your diet lacking in iodine-rich foods, like seaweed or fish? | D11: https://aim-dashboard.internal.babylontech.co.uk/concept/Q29uY2VwdDowMGJlMTdjZS1iZDE1LTQ4ZjAtOWIzNS1hNTY3OTk1OWExNTI= | E11: True | F11: unisex | G11: 00be17ce-bd15-48f0-9b35-a5679959a152_present | H11: 00be17ce-bd15-48f0-9b35-a5679959a152 | I11: node_00be17ce-bd15-48f0-9b35-a5679959a152_layman_question_yes | J11: Yes | K11: present | L11: False
A12: 00be17ce-bd15-48f0-9b35-a5679959a152 | B12: node_00be17ce-bd15-48f0-9b35-a5679959a152_layman_question | C12: Is your diet lacking in iodine-rich foods, like seaweed or fish? | D12: https://aim-dashboard.internal.babylontech.co.uk/concept/Q29uY2VwdDowMGJlMTdjZS1iZDE1LTQ4ZjAtOWIzNS1hNTY3OTk1OWExNTI= | E12: True | F12: unisex | G12: 00be17ce-bd15-48f0-9b35-a5679959a152_absent | H12: 00be17ce-bd15-48f0-9b35-a5679959a152 | I12: node_00be17ce-bd15-48f0-9b35-a5679959a152_layman_question_no | J12: No | K12: absent | L12: False
A13: 00be17ce-bd15-48f0-9b35-a5679959a152 | B13: node_00be17ce-bd15-48f0-9b35-a5679959a152_layman_question | C13: Is your diet lacking in iodine-rich foods, like seaweed or fish? | D13: https://aim-dashboard.internal.babylontech.co.uk/concept/Q29uY2VwdDowMGJlMTdjZS1iZDE1LTQ4ZjAtOWIzNS1hNTY3OTk1OWExNTI= | E13: True | F13: unisex | G13: 00be17ce-bd15-48f0-9b35-a5679959a152_unknown | I13: dont_know | J13: I don't know | K13: unknown | L13: False
A14: 00e3e875-e2b7-460a-ba39-465eb823d8b6 | B14: question_00e3e875-e2b7-460a-ba39-465eb823d8b6_text | C14: Where is the pain in your finger or fingers? | D14: https://aim-dashboard.internal.babylontech.co.uk/questions/UXVlc3Rpb246MDBlM2U4NzUtZTJiNy00NjBhLWJhMzktNDY1ZWI4MjNkOGI2 | E14: True | F14: unisex | G14: 3842e20c-defc-4d97-96b2-ab5d356932a6 | H14: d013c831-3980-4786-81b7-054a3a82cbae | I14: answer_3842e20c-defc-4d97-96b2-ab5d356932a6_text | J14: The finger joint below my nail | K14: present | L14: True
A15: 00e3e875-e2b7-460a-ba39-465eb823d8b6 | B15: question_00e3e875-e2b7-460a-ba39-465eb823d8b6_text | C15: Where is the pain in your finger or fingers? | D15: https://aim-dashboard.internal.babylontech.co.uk/questions/UXVlc3Rpb246MDBlM2U4NzUtZTJiNy00NjBhLWJhMzktNDY1ZWI4MjNkOGI2 | E15: True | F15: unisex | G15: 053ec21e-98d0-4e67-92b2-d7389aa9d543 | H15: 2e1a6ba6-e4c3-409d-b1d2-52ec8cd7a71e | I15: answer_053ec21e-98d0-4e67-92b2-d7389aa9d543_text | J15: The joint in the middle of my finger | K15: present | L15: True
A16: 00e3e875-e2b7-460a-ba39-465eb823d8b6 | B16: question_00e3e875-e2b7-460a-ba39-465eb823d8b6_text | C16: Where is the pain in your finger or fingers? | D16: https://aim-dashboard.internal.babylontech.co.uk/questions/UXVlc3Rpb246MDBlM2U4NzUtZTJiNy00NjBhLWJhMzktNDY1ZWI4MjNkOGI2 | E16: True | F16: unisex | G16: 00e3e875-e2b7-460a-ba39-465eb823d8b6_none | I16: question_00e3e875-e2b7-460a-ba39-465eb823d8b6_none_text | J16: Somewhere else | K16: absent | L16: False
A17: 01029c68-0a2a-4a0c-872d-10311a774b61 | B17: node_01029c68-0a2a-4a0c-872d-10311a774b61_layman_question | C17: Is you top-mid abdominal pain worse when lying down? | D17: https://aim-dashboard.internal.babylontech.co.uk/concept/Q29uY2VwdDowMTAyOWM2OC0wYTJhLTRhMGMtODcyZC0xMDMxMWE3NzRiNjE= | E17: True | F17: unisex | G17: 01029c68-0a2a-4a0c-872d-10311a774b61_present | H17: 01029c68-0a2a-4a0c-872d-10311a774b61 | I17: node_01029c68-0a2a-4a0c-872d-10311a774b61_layman_question_yes | J17: Yes | K17: present | L17: False
A18: 01029c68-0a2a-4a0c-872d-10311a774b61 | B18: node_01029c68-0a2a-4a0c-872d-10311a774b61_layman_question | C18: Is you top-mid abdominal pain worse when lying down? | D18: https://aim-dashboard.internal.babylontech.co.uk/concept/Q29uY2VwdDowMTAyOWM2OC0wYTJhLTRhMGMtODcyZC0xMDMxMWE3NzRiNjE= | E18: True | F18: unisex | G18: 01029c68-0a2a-4a0c-872d-10311a774b61_absent | H18: 01029c68-0a2a-4a0c-872d-10311a774b61 | I18: node_01029c68-0a2a-4a0c-872d-10311a774b61_layman_question_no | J18: No | K18: absent | L18: False
A19: 01029c68-0a2a-4a0c-872d-10311a774b61 | B19: node_01029c68-0a2a-4a0c-872d-10311a774b61_layman_question | C19: Is you top-mid abdominal pain worse when lying down? | D19: https://aim-dashboard.internal.babylontech.co.uk/concept/Q29uY2VwdDowMTAyOWM2OC0wYTJhLTRhMGMtODcyZC0xMDMxMWE3NzRiNjE= | E19: True | F19: unisex | G19: 01029c68-0a2a-4a0c-872d-10311a774b61_unknown | I19: dont_know | J19: I don't know | K19: unknown | L19: False
A20: 0149095c-6184-5a0b-96c6-10fb339e6ebe | B20: node_51e635a1-4937-4098-afa3-372a644185d4_layman_question | C20: Have you been diagnosed with bile duct cancer? | D20: https://aim-dashboard.internal.babylontech.co.uk/concept/Q29uY2VwdDowMTQ5MDk1Yy02MTg0LTVhMGItOTZjNi0xMGZiMzM5ZTZlYmU= | E20: True | F20: unisex | G20: 0149095c-6184-5a0b-96c6-10fb339e6ebe_present | H20: 0149095c-6184-5a0b-96c6-10fb339e6ebe | I20: node_51e635a1-4937-4098-afa3-372a644185d4_layman_question_yes | J20: Yes | K20: present | L20: False
A21: 0149095c-6184-5a0b-96c6-10fb339e6ebe | B21: node_51e635a1-4937-4098-afa3-372a644185d4_layman_question | C21: Have you been diagnosed with bile duct cancer? | D21: https://aim-dashboard.internal.babylontech.co.uk/concept/Q29uY2VwdDowMTQ5MDk1Yy02MTg0LTVhMGItOTZjNi0xMGZiMzM5ZTZlYmU= | E21: True | F21: unisex | G21: 0149095c-6184-5a0b-96c6-10fb339e6ebe_absent | H21: 0149095c-6184-5a0b-96c6-10fb339e6ebe | I21: node_51e635a1-4937-4098-afa3-372a644185d4_layman_question_no | J21: No | K21: absent | L21: False
A22: 0149095c-6184-5a0b-96c6-10fb339e6ebe | B22: node_51e635a1-4937-4098-afa3-372a644185d4_layman_question | C22: Have you been diagnosed with bile duct cancer? | D22: https://aim-dashboard.internal.babylontech.co.uk/concept/Q29uY2VwdDowMTQ5MDk1Yy02MTg0LTVhMGItOTZjNi0xMGZiMzM5ZTZlYmU= | E22: True | F22: unisex | G22: 0149095c-6184-5a0b-96c6-10fb339e6ebe_unknown | I22: dont_know | J22: I don't know | K22: unknown | L22: False
A23: 0193e1b5-fd51-451c-bf0f-70ee849c079f | B23: question_0193e1b5-fd51-451c-bf0f-70ee849c079f_text | C23: When you have sex, where is the pain in your vagina? | D23: https://aim-dashboard.internal.babylontech.co.uk/questions/UXVlc3Rpb246MDE5M2UxYjUtZmQ1MS00NTFjLWJmMGYtNzBlZTg0OWMwNzlm | E23: True | F23: female_only | G23: 5f81e606-ee06-44e9-8fbb-6da6d23bf41a | H23: 9899d2c6-a37b-4c68-b6ea-415654d0ae2a | I23: answer_5f81e606-ee06-44e9-8fbb-6da6d23bf41a_text | J23: At the entrance or around the outside | K23: present | L23: True
A24: 0193e1b5-fd51-451c-bf0f-70ee849c079f | B24: question_0193e1b5-fd51-451c-bf0f-70ee849c079f_text | C24: When you have sex, where is the pain in your vagina? | D24: https://aim-dashboard.internal.babylontech.co.uk/questions/UXVlc3Rpb246MDE5M2UxYjUtZmQ1MS00NTFjLWJmMGYtNzBlZTg0OWMwNzlm | E24: True | F24: female_only | G24: b077d938-f1f0-421d-87b9-80c24abbed06 | H24: e2d8a490-efb1-45c6-b807-25b183e20c9f | I24: answer_b077d938-f1f0-421d-87b9-80c24abbed06_text | J24: Deep inside | K24: present | L24: True
A25: 0193e1b5-fd51-451c-bf0f-70ee849c079f | B25: question_0193e1b5-fd51-451c-bf0f-70ee849c079f_text | C25: When you have sex, where is the pain in your vagina? | D25: https://aim-dashboard.internal.babylontech.co.uk/questions/UXVlc3Rpb246MDE5M2UxYjUtZmQ1MS00NTFjLWJmMGYtNzBlZTg0OWMwNzlm | E25: True | F25: female_only | G25: 0193e1b5-fd51-451c-bf0f-70ee849c079f_unknown | I25: dont_know | J25: I don't know | K25: unknown | L25: False
A26: 019b0e3a-d932-4694-8014-c4c7615d6191 | B26: node_019b0e3a-d932-4694-8014-c4c7615d6191_layman_question | C26: Have you had sex in the last 6 months without using condoms and without being covered by another form of reliable contraception which you use effectively? | D26: https://aim-dashboard.internal.babylontech.co.uk/concept/Q29uY2VwdDowMTliMGUzYS1kOTMyLTQ2OTQtODAxNC1jNGM3NjE1ZDYxOTE= | E26: True | F26: female_only | G26: 019b0e3a-d932-4694-8014-c4c7615d6191_present | H26: 019b0e3a-d932-4694-8014-c4c7615d6191 | I26: node_019b0e3a-d932-4694-8014-c4c7615d6191_layman_question_yes | J26: Yes | K26: present | L26: False
A27: 019b0e3a-d932-4694-8014-c4c7615d6191 | B27: node_019b0e3a-d932-4694-8014-c4c7615d6191_layman_question | C27: Have you had sex in the last 6 months without using condoms and without being covered by another form of reliable contraception which you use effectively? | D27: https://aim-dashboard.internal.babylontech.co.uk/concept/Q29uY2VwdDowMTliMGUzYS1kOTMyLTQ2OTQtODAxNC1jNGM3NjE1ZDYxOTE= | E27: True | F27: female_only | G27: 019b0e3a-d932-4694-8014-c4c7615d6191_absent | H27: 019b0e3a-d932-4694-8014-c4c7615d6191 | I27: node_019b0e3a-d932-4694-8014-c4c7615d6191_layman_question_no | J27: No | K27: absent | L27: False
A28: 019b0e3a-d932-4694-8014-c4c7615d6191 | B28: node_019b0e3a-d932-4694-8014-c4c7615d6191_layman_question | C28: Have you had sex in the last 6 months without using condoms and without being covered by another form of reliable contraception which you use effectively? | D28: https://aim-dashboard.internal.babylontech.co.uk/concept/Q29uY2VwdDowMTliMGUzYS1kOTMyLTQ2OTQtODAxNC1jNGM3NjE1ZDYxOTE= | E28: True | F28: female_only | G28: 019b0e3a-d932-4694-8014-c4c7615d6191_unknown | I28: dont_know | J28: I don't know | K28: unknown | L28: False
A29: 023cb322-5a92-4e38-bf07-a9aa0fbe28bb | B29: question_023cb322-5a92-4e38-bf07-a9aa0fbe28bb_text | C29: Does your top middle abdominal pain come and go or is it there constantly? | D29: https://aim-dashboard.internal.babylontech.co.uk/questions/UXVlc3Rpb246MDIzY2IzMjItNWE5Mi00ZTM4LWJmMDctYTlhYTBmYmUyOGJi | E29: True | F29: unisex | G29: 58ddb338-1d8c-4001-9e3d-c078641802a1 | H29: 0f0c86a2-0729-47e8-9761-6d7cc17e7838 | I29: answer_58ddb338-1d8c-4001-9e3d-c078641802a1_text | J29: It's constant | K29: present | L29: False
A30: 023cb322-5a92-4e38-bf07-a9aa0fbe28bb | B30: question_023cb322-5a92-4e38-bf07-a9aa0fbe28bb_text | C30: Does your top middle abdominal pain come and go or is it there constantly? | D30: https://aim-dashboard.internal.babylontech.co.uk/questions/UXVlc3Rpb246MDIzY2IzMjItNWE5Mi00ZTM4LWJmMDctYTlhYTBmYmUyOGJi | E30: True | F30: unisex | G30: b1feb576-8298-4ceb-bffd-5b39da10d072 | H30: cfdc1f91-be39-43ba-adee-8c6f073dc96a | I30: answer_b1feb576-8298-4ceb-bffd-5b39da10d072_text | J30: The pain comes and goes | K30: present | L30: False
A31: 025ddbca-dbe4-5268-929c-ba0a8c3a36a2 | B31: node_212765ec-e8e8-41f6-995b-4c623df8d8bb_layman_question | C31: Have you been diagnosed with chronic lymphocytic leukemia (CLL)? | D31: https://aim-dashboard.internal.babylontech.co.uk/concept/Q29uY2VwdDowMjVkZGJjYS1kYmU0LTUyNjgtOTI5Yy1iYTBhOGMzYTM2YTI= | E31: True | F31: unisex | G31: 025ddbca-dbe4-5268-929c-ba0a8c3a36a2_present | H31: 025ddbca-dbe4-5268-929c-ba0a8c3a36a2 | I31: node_212765ec-e8e8-41f6-995b-4c623df8d8bb_layman_question_yes | J31: Yes | K31: present | L31: False
A32: 025ddbca-dbe4-5268-929c-ba0a8c3a36a2 | B32: node_212765ec-e8e8-41f6-995b-4c623df8d8bb_layman_question | C32: Have you been diagnosed with chronic lymphocytic leukemia (CLL)? | D32: https://aim-dashboard.internal.babylontech.co.uk/concept/Q29uY2VwdDowMjVkZGJjYS1kYmU0LTUyNjgtOTI5Yy1iYTBhOGMzYTM2YTI= | E32: True | F32: unisex | G32: 025ddbca-dbe4-5268-929c-ba0a8c3a36a2_absent | H32: 025ddbca-dbe4-5268-929c-ba0a8c3a36a2 | I32: node_212765ec-e8e8-41f6-995b-4c623df8d8bb_layman_question_no | J32: No | K32: absent | L32: False
A33: 025ddbca-dbe4-5268-929c-ba0a8c3a36a2 | B33: node_212765ec-e8e8-41f6-995b-4c623df8d8bb_layman_question | C33: Have you been diagnosed with chronic lymphocytic leukemia (CLL)? | D33: https://aim-dashboard.internal.babylontech.co.uk/concept/Q29uY2VwdDowMjVkZGJjYS1kYmU0LTUyNjgtOTI5Yy1iYTBhOGMzYTM2YTI= | E33: True | F33: unisex | G33: 025ddbca-dbe4-5268-929c-ba0a8c3a36a2_unknown | I33: dont_know | J33: I don't know | K33: unknown | L33: False
A34: 029177e2-337b-4a7d-a596-cd4779c6471e | B34: node_029177e2-337b-4a7d-a596-cd4779c6471e_layman_question | C34: Have you ever had a panic attack? | D34: https://aim-dashboard.internal.babylontech.co.uk/concept/Q29uY2VwdDowMjkxNzdlMi0zMzdiLTRhN2QtYTU5Ni1jZDQ3NzljNjQ3MWU= | E34: True | F34: unisex | G34: 029177e2-337b-4a7d-a596-cd4779c6471e_present | H34: 029177e2-337b-4a7d-a596-cd4779c6471e | I34: node_029177e2-337b-4a7d-a596-cd4779c6471e_layman_question_yes | J34: Yes | K34: present | L34: False
A35: 029177e2-337b-4a7d-a596-cd4779c6471e | B35: node_029177e2-337b-4a7d-a596-cd4779c6471e_layman_question | C35: Have you ever had a panic attack? | D35: https://aim-dashboard.internal.babylontech.co.uk/concept/Q29uY2VwdDowMjkxNzdlMi0zMzdiLTRhN2QtYTU5Ni1jZDQ3NzljNjQ3MWU= | E35: True | F35: unisex | G35: 029177e2-337b-4a7d-a596-cd4779c6471e_absent | H35: 029177e2-337b-4a7d-a596-cd4779c6471e | I35: node_029177e2-337b-4a7d-a596-cd4779c6471e_layman_question_no | J35: No | K35: absent | L35: False
A36: 029177e2-337b-4a7d-a596-cd4779c6471e | B36: node_029177e2-337b-4a7d-a596-cd4779c6471e_layman_question | C36: Have you ever had a panic attack? | D36: https://aim-dashboard.internal.babylontech.co.uk/concept/Q29uY2VwdDowMjkxNzdlMi0zMzdiLTRhN2QtYTU5Ni1jZDQ3NzljNjQ3MWU= | E36: True | F36: unisex | G36: 029177e2-337b-4a7d-a596-cd4779c6471e_unknown | I36: dont_know | J36: I don't know | K36: unknown | L36: False
A37: 02c2d502-49ab-4ce9-89a4-a4bcb51732f1 | B37: node_02c2d502-49ab-4ce9-89a4-a4bcb51732f1_layman_question | C37: Have you noticed a lump or swelling in the left lower part of the stomach which used to come and go but is now stuck out? | D37: https://aim-dashboard.internal.babylontech.co.uk/concept/Q29uY2VwdDowMmMyZDUwMi00OWFiLTRjZTktODlhNC1hNGJjYjUxNzMyZjE= | E37: True | F37: unisex | G37: 02c2d502-49ab-4ce9-89a4-a4bcb51732f1_present | H37: 02c2d502-49ab-4ce9-89a4-a4bcb51732f1 | I37: node_02c2d502-49ab-4ce9-89a4-a4bcb51732f1_layman_question_yes | J37: Yes | K37: present | L37: False
A38: 02c2d502-49ab-4ce9-89a4-a4bcb51732f1 | B38: node_02c2d502-49ab-4ce9-89a4-a4bcb51732f1_layman_question | C38: Have you noticed a lump or swelling in the left lower part of the stomach which used to come and go but is now stuck out? | D38: https://aim-dashboard.internal.babylontech.co.uk/concept/Q29uY2VwdDowMmMyZDUwMi00OWFiLTRjZTktODlhNC1hNGJjYjUxNzMyZjE= | E38: True | F38: unisex | G38: 02c2d502-49ab-4ce9-89a4-a4bcb51732f1_absent | H38: 02c2d502-49ab-4ce9-89a4-a4bcb51732f1 | I38: node_02c2d502-49ab-4ce9-89a4-a4bcb51732f1_layman_question_no | J38: No | K38: absent | L38: False
A39: 02c2d502-49ab-4ce9-89a4-a4bcb51732f1 | B39: node_02c2d502-49ab-4ce9-89a4-a4bcb51732f1_layman_question | C39: Have you noticed a lump or swelling in the left lower part of the stomach which used to come and go but is now stuck out? | D39: https://aim-dashboard.internal.babylontech.co.uk/concept/Q29uY2VwdDowMmMyZDUwMi00OWFiLTRjZTktODlhNC1hNGJjYjUxNzMyZjE= | E39: True | F39: unisex | G39: 02c2d502-49ab-4ce9-89a4-a4bcb51732f1_unknown | I39: dont_know | J39: I don't know | K39: unknown | L39: False
